{"trial_id": "0000", "hyperparameters": {"space": [{"class_name": "Int", "config": {"name": "n_layers", "default": null, "conditions": [], "min_value": 2, "max_value": 4, "step": 1, "sampling": "linear"}}, {"class_name": "Int", "config": {"name": "n_filter_maps", "default": null, "conditions": [], "min_value": 16, "max_value": 32, "step": 8, "sampling": "linear"}}, {"class_name": "Choice", "config": {"name": "learning_rate", "default": 0.01, "conditions": [], "values": [0.01, 0.001, 0.0001], "ordered": true}}, {"class_name": "Boolean", "config": {"name": "image_only", "default": false, "conditions": []}}], "values": {"n_layers": 4, "n_filter_maps": 16, "learning_rate": 0.0001, "image_only": true, "tuner/epochs": 3, "tuner/initial_epoch": 0, "tuner/bracket": 2, "tuner/round": 0}}, "metrics": {"metrics": {}}, "score": null, "best_step": 0, "status": "FAILED", "message": "Traceback (most recent call last):\n  File \"/home/sai/.local/lib/python3.10/site-packages/keras_tuner/src/engine/base_tuner.py\", line 274, in _try_run_and_update_trial\n    self._run_and_update_trial(trial, *fit_args, **fit_kwargs)\n  File \"/home/sai/.local/lib/python3.10/site-packages/keras_tuner/src/engine/base_tuner.py\", line 239, in _run_and_update_trial\n    results = self.run_trial(trial, *fit_args, **fit_kwargs)\n  File \"/home/sai/.local/lib/python3.10/site-packages/keras_tuner/src/tuners/hyperband.py\", line 427, in run_trial\n    return super().run_trial(trial, *fit_args, **fit_kwargs)\n  File \"/home/sai/.local/lib/python3.10/site-packages/keras_tuner/src/engine/tuner.py\", line 314, in run_trial\n    obj_value = self._build_and_fit_model(trial, *args, **copied_kwargs)\n  File \"/home/sai/.local/lib/python3.10/site-packages/keras_tuner/src/engine/tuner.py\", line 233, in _build_and_fit_model\n    results = self.hypermodel.fit(hp, model, *args, **kwargs)\n  File \"/home/sai/.local/lib/python3.10/site-packages/keras_tuner/src/engine/hypermodel.py\", line 149, in fit\n    return model.fit(*args, **kwargs)\n  File \"/home/sai/.local/lib/python3.10/site-packages/keras/src/utils/traceback_utils.py\", line 122, in error_handler\n    raise e.with_traceback(filtered_tb) from None\n  File \"/home/sai/.local/lib/python3.10/site-packages/keras/src/layers/input_spec.py\", line 160, in assert_input_compatibility\n    raise ValueError(\nValueError: Layer \"functional\" expects 1 input(s), but it received 2 input tensors. Inputs received: [<tf.Tensor 'data:0' shape=(None, 400, 400, 3) dtype=float32>, <tf.Tensor 'data_1:0' shape=(None, 9) dtype=float64>]\n"}